[2023-01-02 15:54]  INFO [base.py start] [ line:166 ] Scheduler started
[2023-01-02 15:54]  ERROR [updater.py _network_loop_retry] [ line:664 ] Error while getting Updates: Conflict: terminated by other getUpdates request; make sure that only one bot instance is running
[2023-01-02 15:54]  ERROR [dispatcher.py dispatch_error] [ line:821 ] No error handlers are registered, logging exception.
Traceback (most recent call last):
  File "C:\Users\USER\AppData\Local\Programs\Python\Python310\lib\site-packages\telegram\ext\updater.py", line 651, in _network_loop_retry
    if not action_cb():
  File "C:\Users\USER\AppData\Local\Programs\Python\Python310\lib\site-packages\telegram\ext\updater.py", line 602, in polling_action_cb
    updates = self.bot.get_updates(
  File "C:\Users\USER\AppData\Local\Programs\Python\Python310\lib\site-packages\telegram\ext\extbot.py", line 226, in get_updates
    updates = super().get_updates(
  File "C:\Users\USER\AppData\Local\Programs\Python\Python310\lib\site-packages\telegram\bot.py", line 133, in decorator
    result = func(*args, **kwargs)
  File "C:\Users\USER\AppData\Local\Programs\Python\Python310\lib\site-packages\telegram\bot.py", line 3057, in get_updates
    self._post(
  File "C:\Users\USER\AppData\Local\Programs\Python\Python310\lib\site-packages\telegram\bot.py", line 298, in _post
    return self.request.post(
  File "C:\Users\USER\AppData\Local\Programs\Python\Python310\lib\site-packages\telegram\utils\request.py", line 361, in post
    result = self._request_wrapper(
  File "C:\Users\USER\AppData\Local\Programs\Python\Python310\lib\site-packages\telegram\utils\request.py", line 283, in _request_wrapper
    raise Conflict(message)
telegram.error.Conflict: Conflict: terminated by other getUpdates request; make sure that only one bot instance is running
